<?xml version="1.0"?>
<robot xmlns:xacro="http://www.ros.org/wiki/xacro" name="simple_amr_sim">

    <!--................................ INERTIA MATRICES .............................. -->

    <xacro:macro name="cylinder_inertia" params="m r h">
        <inertia ixx="${m * (3 * r * r + h * h) / 12}" ixy="0" ixz="0" iyy="${m * (3 * r * r + h * h) / 12}" iyz="0" izz="${m * r * r / 2}" />
    </xacro:macro>

    <xacro:macro name="box_inertia" params="m x y z">
        <inertia ixx="${m * (y * y + z * z) / 12}" ixy="0" ixz="0" iyy="${m * (x * x + z * z) / 12}" iyz="0" izz="${m * (y * y + x * x) / 12}" />
    </xacro:macro>

    <xacro:macro name="sphere_inertia" params="m r">
        <inertia ixx="${2 * m * r * r / 5}" ixy="0" ixz="0" iyy="${2 * m * r * r / 5}" iyz="0" izz="${2 * m * r * r / 5}" />
    </xacro:macro>

    <!-- ............................... TROLLEY WHEEL DEFINITION .............................. -->

    <xacro:macro name="trolley_wheel" params="cardinality dexterity origin_x origin_y origin_z">
        <link name="${cardinality}_${dexterity}_wheel">
          

            <mu>0.0</mu>
        </link>

        <joint name="${cardinality}_${dexterity}_wheel_joint" type="fixed">
            <parent link="base_link"/>
            <child link="${cardinality}_${dexterity}_wheel"/>
            <origin xyz="${origin_x} ${origin_y} ${origin_z}" rpy="0 0 0" />
            <axis xyz="0 1 0" rpy="0 0 0" />
        </joint>

        <gazebo reference="${cardinality}_${dexterity}_wheel">
            <material>Gazebo/Black</material>
        </gazebo>
    </xacro:macro>

    <xacro:macro name="traction_wheel_1" params="cardinality dexterity origin_x origin_y origin_z">
        <link name="${cardinality}_${dexterity}_wheel">
            <collision>
                <origin xyz="0 0 0" rpy="${pi/2} 0 0" />
                <geometry>
                    <cylinder length="${traction_wheel_width_1}" radius="${traction_wheel_radius_1}"/>
                </geometry>
            </collision>
            
            <visual>
                <origin xyz="0 0 0" rpy="${pi/2} 0 0" />
                <geometry>
                    <cylinder length="${traction_wheel_width_1}" radius="${traction_wheel_radius_1}"/>
                </geometry>
                <material name="black"/>
            </visual>

            <inertial>
                <origin xyz="0 0 0" rpy="${pi/2} 0 0" />
                <mass value="${traction_wheel_mass_1}"/>
                <xacro:cylinder_inertia m="${traction_wheel_mass_1}" r="${traction_wheel_radius_1}" h="${traction_wheel_width_1}"/>
            </inertial>

            <mu>5.0</mu>
        </link>

        <joint name="${cardinality}_${dexterity}_wheel_joint" type="continuous">
            <parent link="base_link"/>
            <child link="${cardinality}_${dexterity}_wheel"/>
            <origin xyz="${origin_x} ${origin_y} ${origin_z}" rpy="0 0 0" />
            <axis xyz="0 1 0" rpy="0 0 0" />
        </joint>

        <gazebo reference="${cardinality}_${dexterity}_wheel">
            <material>Gazebo/Black</material>
            <mu1>${traction_wheel_static_friction_1}</mu1> <!-- Static friction coefficient -->
    	    <mu2>${traction_wheel_dynamic_friction_1}</mu2> <!-- Dynamic friction coefficient -->
        </gazebo>
    </xacro:macro>
    
    
     <xacro:macro name="traction_wheel_2" params="cardinality dexterity origin_x origin_y origin_z">
        <link name="${cardinality}_${dexterity}_wheel">
            <collision>
                <origin xyz="0 0 0" rpy="${pi/2} 0 0" />
                <geometry>
                    <cylinder length="${traction_wheel_width_2}" radius="${traction_wheel_radius_2}"/>
                </geometry>
            </collision>
            
            <visual>
                <origin xyz="0 0 0" rpy="${pi/2} 0 0" />
                <geometry>
                    <cylinder length="${traction_wheel_width_2}" radius="${traction_wheel_radius_2}"/>
                </geometry>
                <material name="black"/>
            </visual>

            <inertial>
                <origin xyz="0 0 0" rpy="${pi/2} 0 0" />
                <mass value="${traction_wheel_mass_2}"/>
                <xacro:cylinder_inertia m="${traction_wheel_mass_2}" r="${traction_wheel_radius_2}" h="${traction_wheel_width_2}"/>
            </inertial>

            <mu>5.0</mu>
        </link>

        <joint name="${cardinality}_${dexterity}_wheel_joint" type="continuous">
            <parent link="base_link"/>
            <child link="${cardinality}_${dexterity}_wheel"/>
            <origin xyz="${origin_x} ${origin_y} ${origin_z}" rpy="0 0 0" />
            <axis xyz="0 1 0" rpy="0 0 0" />
        </joint>

        <gazebo reference="${cardinality}_${dexterity}_wheel">
            <material>Gazebo/Black</material>
            <mu1>${traction_wheel_static_friction_2}</mu1> <!-- Static friction coefficient -->
    	    <mu2>${traction_wheel_dynamic_friction_2}</mu2> <!-- Dynamic friction coefficient -->
        </gazebo>
    </xacro:macro>

</robot>
